modules loaded
beginning preprocessing
/usr/local/miniconda/lib/python3.7/site-packages/bids/layout/validation.py:46: UserWarning: The ability to pass arguments to BIDSLayout that control indexing is likely to be removed in future; possibly as early as PyBIDS 0.14. This includes the `config_filename`, `ignore`, `force_index`, and `index_metadata` arguments. The recommended usage pattern is to initialize a new BIDSLayoutIndexer with these arguments, and pass it to the BIDSLayout via the `indexer` argument.
  warnings.warn("The ability to pass arguments to BIDSLayout that control "
Traceback (most recent call last):
  File "/usr/local/miniconda/lib/python3.7/site-packages/sqlalchemy/engine/base.py", line 2338, in _wrap_pool_connect
    return fn()
  File "/usr/local/miniconda/lib/python3.7/site-packages/sqlalchemy/pool/base.py", line 364, in connect
    return _ConnectionFairy._checkout(self)
  File "/usr/local/miniconda/lib/python3.7/site-packages/sqlalchemy/pool/base.py", line 778, in _checkout
    fairy = _ConnectionRecord.checkout(pool)
  File "/usr/local/miniconda/lib/python3.7/site-packages/sqlalchemy/pool/base.py", line 495, in checkout
    rec = pool._do_get()
  File "/usr/local/miniconda/lib/python3.7/site-packages/sqlalchemy/pool/impl.py", line 239, in _do_get
    return self._create_connection()
  File "/usr/local/miniconda/lib/python3.7/site-packages/sqlalchemy/pool/base.py", line 309, in _create_connection
    return _ConnectionRecord(self)
  File "/usr/local/miniconda/lib/python3.7/site-packages/sqlalchemy/pool/base.py", line 440, in __init__
    self.__connect(first_connect_check=True)
  File "/usr/local/miniconda/lib/python3.7/site-packages/sqlalchemy/pool/base.py", line 661, in __connect
    pool.logger.debug("Error on connect(): %s", e)
  File "/usr/local/miniconda/lib/python3.7/site-packages/sqlalchemy/util/langhelpers.py", line 69, in __exit__
    exc_value, with_traceback=exc_tb,
  File "/usr/local/miniconda/lib/python3.7/site-packages/sqlalchemy/util/compat.py", line 182, in raise_
    raise exception
  File "/usr/local/miniconda/lib/python3.7/site-packages/sqlalchemy/pool/base.py", line 656, in __connect
    connection = pool._invoke_creator(self)
  File "/usr/local/miniconda/lib/python3.7/site-packages/sqlalchemy/engine/strategies.py", line 114, in connect
    return dialect.connect(*cargs, **cparams)
  File "/usr/local/miniconda/lib/python3.7/site-packages/sqlalchemy/engine/default.py", line 493, in connect
    return self.dbapi.connect(*cargs, **cparams)
sqlite3.OperationalError: unable to open database file

The above exception was the direct cause of the following exception:

Traceback (most recent call last):
  File "/usr/local/miniconda/bin/fmriprep", line 10, in <module>
    sys.exit(main())
  File "/usr/local/miniconda/lib/python3.7/site-packages/fmriprep/cli/run.py", line 17, in main
    parse_args()
  File "/usr/local/miniconda/lib/python3.7/site-packages/fmriprep/cli/parser.py", line 696, in parse_args
    all_subjects = config.execution.layout.get_subjects()
  File "/usr/local/miniconda/lib/python3.7/site-packages/bids/layout/layout.py", line 173, in __getattr__
    entities = self.get_entities()
  File "/usr/local/miniconda/lib/python3.7/site-packages/bids/layout/layout.py", line 372, in get_entities
    results = query.all()
  File "/usr/local/miniconda/lib/python3.7/site-packages/sqlalchemy/orm/query.py", line 3346, in all
    return list(self)
  File "/usr/local/miniconda/lib/python3.7/site-packages/sqlalchemy/orm/query.py", line 3508, in __iter__
    return self._execute_and_instances(context)
  File "/usr/local/miniconda/lib/python3.7/site-packages/sqlalchemy/orm/query.py", line 3530, in _execute_and_instances
    querycontext, self._connection_from_session, close_with_result=True
  File "/usr/local/miniconda/lib/python3.7/site-packages/sqlalchemy/orm/query.py", line 3545, in _get_bind_args
    mapper=self._bind_mapper(), clause=querycontext.statement, **kw
  File "/usr/local/miniconda/lib/python3.7/site-packages/sqlalchemy/orm/query.py", line 3523, in _connection_from_session
    conn = self.session.connection(**kw)
  File "/usr/local/miniconda/lib/python3.7/site-packages/sqlalchemy/orm/session.py", line 1141, in connection
    execution_options=execution_options,
  File "/usr/local/miniconda/lib/python3.7/site-packages/sqlalchemy/orm/session.py", line 1147, in _connection_for_bind
    engine, execution_options
  File "/usr/local/miniconda/lib/python3.7/site-packages/sqlalchemy/orm/session.py", line 433, in _connection_for_bind
    conn = bind._contextual_connect()
  File "/usr/local/miniconda/lib/python3.7/site-packages/sqlalchemy/engine/base.py", line 2304, in _contextual_connect
    self._wrap_pool_connect(self.pool.connect, None),
  File "/usr/local/miniconda/lib/python3.7/site-packages/sqlalchemy/engine/base.py", line 2342, in _wrap_pool_connect
    e, dialect, self
  File "/usr/local/miniconda/lib/python3.7/site-packages/sqlalchemy/engine/base.py", line 1584, in _handle_dbapi_exception_noconnection
    sqlalchemy_exception, with_traceback=exc_info[2], from_=e
  File "/usr/local/miniconda/lib/python3.7/site-packages/sqlalchemy/util/compat.py", line 182, in raise_
    raise exception
  File "/usr/local/miniconda/lib/python3.7/site-packages/sqlalchemy/engine/base.py", line 2338, in _wrap_pool_connect
    return fn()
  File "/usr/local/miniconda/lib/python3.7/site-packages/sqlalchemy/pool/base.py", line 364, in connect
    return _ConnectionFairy._checkout(self)
  File "/usr/local/miniconda/lib/python3.7/site-packages/sqlalchemy/pool/base.py", line 778, in _checkout
    fairy = _ConnectionRecord.checkout(pool)
  File "/usr/local/miniconda/lib/python3.7/site-packages/sqlalchemy/pool/base.py", line 495, in checkout
    rec = pool._do_get()
  File "/usr/local/miniconda/lib/python3.7/site-packages/sqlalchemy/pool/impl.py", line 239, in _do_get
    return self._create_connection()
  File "/usr/local/miniconda/lib/python3.7/site-packages/sqlalchemy/pool/base.py", line 309, in _create_connection
    return _ConnectionRecord(self)
  File "/usr/local/miniconda/lib/python3.7/site-packages/sqlalchemy/pool/base.py", line 440, in __init__
    self.__connect(first_connect_check=True)
  File "/usr/local/miniconda/lib/python3.7/site-packages/sqlalchemy/pool/base.py", line 661, in __connect
    pool.logger.debug("Error on connect(): %s", e)
  File "/usr/local/miniconda/lib/python3.7/site-packages/sqlalchemy/util/langhelpers.py", line 69, in __exit__
    exc_value, with_traceback=exc_tb,
  File "/usr/local/miniconda/lib/python3.7/site-packages/sqlalchemy/util/compat.py", line 182, in raise_
    raise exception
  File "/usr/local/miniconda/lib/python3.7/site-packages/sqlalchemy/pool/base.py", line 656, in __connect
    connection = pool._invoke_creator(self)
  File "/usr/local/miniconda/lib/python3.7/site-packages/sqlalchemy/engine/strategies.py", line 114, in connect
    return dialect.connect(*cargs, **cparams)
  File "/usr/local/miniconda/lib/python3.7/site-packages/sqlalchemy/engine/default.py", line 493, in connect
    return self.dbapi.connect(*cargs, **cparams)
sqlalchemy.exc.OperationalError: (sqlite3.OperationalError) unable to open database file
(Background on this error at: http://sqlalche.me/e/13/e3q8)
